
root - WARNING - Bot is currently online-2023-09-21 16:01:41.997857
root - WARNING - Bot is currently polling-2023-09-21 16:01:42.026538
root - WARNING - Bot is currently online-2023-09-21 16:02:01.363456
root - WARNING - Bot is currently polling-2023-09-21 16:02:01.395762
root - WARNING - Bot is currently offline-2023-09-21 16:02:05.542129
asyncio - ERROR - Task was destroyed but it is pending!
task: <Task pending name='Application:6544496390:update_fetcher' coro=<Application._update_fetcher() running at E:\Aviraj_python\theclassmatebot\.venv\Lib\site-packages\telegram\ext\_application.py:1101> wait_for=<Future pending cb=[Task.task_wakeup()]>>
root - WARNING - Bot is currently online-2023-09-21 16:16:59.175666
root - WARNING - Bot is currently polling-2023-09-21 16:16:59.190578
root - WARNING - User:6310472157 :Hi-2023-09-21 16:17:20.085330
asyncio - ERROR - Task was destroyed but it is pending!
task: <Task pending name='Application:6544496390:update_fetcher' coro=<Application._update_fetcher() running at E:\Aviraj_python\theclassmatebot\.venv\Lib\site-packages\telegram\ext\_application.py:1101> wait_for=<Future pending cb=[Task.task_wakeup()]>>
root - WARNING - Bot is currently online-2023-09-21 16:22:21.426213
root - WARNING - Bot is currently polling-2023-09-21 16:22:21.456000
asyncio - ERROR - Task was destroyed but it is pending!
task: <Task pending name='Application:6544496390:update_fetcher' coro=<Application._update_fetcher() running at E:\Aviraj_python\theclassmatebot\.venv\Lib\site-packages\telegram\ext\_application.py:1101> wait_for=<Future pending cb=[Task.task_wakeup()]>>
root - WARNING - Bot is currently online-2023-09-21 16:22:29.819350
root - WARNING - Bot is currently polling-2023-09-21 16:22:29.843429
root - WARNING - Bot is currently online-2023-09-21 16:22:42.576014
root - WARNING - Bot is currently polling-2023-09-21 16:22:42.600016
asyncio - ERROR - Task was destroyed but it is pending!
task: <Task pending name='Application:6544496390:update_fetcher' coro=<Application._update_fetcher() running at E:\Aviraj_python\theclassmatebot\.venv\Lib\site-packages\telegram\ext\_application.py:1101> wait_for=<Future pending cb=[Task.task_wakeup()]>>
root - WARNING - Bot is currently online-2023-10-16 15:11:12.300267
root - WARNING - Bot is currently polling-2023-10-16 15:11:12.864850
root - WARNING - User:6310472157 :/contribution-2023-10-16 15:11:18.368909
root - WARNING - Bot is currently online-2023-10-16 15:23:14.588049
root - WARNING - Bot is currently polling-2023-10-16 15:23:14.619301
root - WARNING - User:6310472157 :Hi-2023-10-16 15:23:56.961013
root - WARNING - Bot is currently online-2023-10-16 15:27:44.581122
root - WARNING - Bot is currently polling-2023-10-16 15:27:44.603262
root - WARNING - Bot is currently online-2023-10-16 15:39:22.767614
root - WARNING - Bot is currently polling-2023-10-16 15:39:22.789753
root - WARNING - Bot is currently online-2023-10-16 15:42:12.797599
root - WARNING - Bot is currently polling-2023-10-16 15:42:12.828854
root - WARNING - Bot is currently online-2023-10-18 22:25:35.325301
root - WARNING - Bot is currently online-2023-10-18 22:32:38.193818
root - WARNING - Bot is currently polling-2023-10-18 22:32:38.620533
root - WARNING - Bot is currently online-2023-10-18 22:36:28.632612
root - WARNING - Bot is currently polling-2023-10-18 22:36:29.101446
root - WARNING - User:6310472157 :Hi-2023-10-18 22:38:53.378087
root - WARNING - Bot is currently online-2023-10-18 22:42:23.952477
root - WARNING - Bot is currently polling-2023-10-18 22:42:24.416920
root - WARNING - User:6310472157 :Ffh-2023-10-18 22:42:33.225343
root - WARNING - Bot is currently online-2023-10-18 22:43:14.349176
root - WARNING - Bot is currently polling-2023-10-18 22:43:14.844281
root - WARNING - User:6310472157 :Test-2023-10-18 22:43:18.701012
root - WARNING - Bot is currently online-2023-10-19 12:51:12.126739
root - WARNING - Bot is currently polling-2023-10-19 12:51:12.150666
root - WARNING - Bot is currently online-2023-10-19 13:21:31.371593
root - WARNING - Bot is currently polling-2023-10-19 13:21:31.387226
root - WARNING - Bot is currently online-2023-10-19 13:32:04.749795
root - WARNING - Bot is currently polling-2023-10-19 13:32:04.770008
root - WARNING - Bot is currently online-2023-10-19 20:31:14.666347
root - WARNING - Bot is currently polling-2023-10-19 20:31:14.791965
root - WARNING - Bot is currently online-2023-10-19 20:32:52.687587
root - WARNING - Bot is currently polling-2023-10-19 20:32:52.733584
root - WARNING - Bot is currently online-2023-10-19 20:43:59.198112
root - WARNING - Bot is currently polling-2023-10-19 20:43:59.229373
root - WARNING - Bot is currently online-2023-10-19 20:44:21.526250
root - WARNING - Bot is currently polling-2023-10-19 20:44:21.551505
telegram.ext.Updater - ERROR - Error while getting Updates: Conflict: terminated by other getUpdates request; make sure that only one bot instance is running
telegram.ext.Application - ERROR - An error was raised and an uncaught error was raised while handling the error with an error_handler.
Traceback (most recent call last):
  File "E:\Aviraj_python\theclassmatebot\.venv\Lib\site-packages\telegram\ext\_application.py", line 1740, in process_error
    await callback(update, context)
  File "e:\Aviraj_python\theclassmatebot\src\main.py", line 219, in error
    f"Update {update} caused the following error {context.error}-{ str(datetime.now())}"
TypeError: error() missing 1 required positional argument: 'context'
telegram.ext.Updater - ERROR - Error while getting Updates: Conflict: terminated by other getUpdates request; make sure that only one bot instance is running
telegram.ext.Application - ERROR - An error was raised and an uncaught error was raised while handling the error with an error_handler.
Traceback (most recent call last):
  File "e:\Aviraj_python\theclassmatebot\.venv\Lib\site-packages\telegram\ext\_application.py", line 1740, in process_error
    await callback(update, context)
  File "e:\Aviraj_python\theclassmatebot\src\main.py", line 218, in error
    error(
TypeError: error() missing 1 required positional argument: 'context'
telegram.ext.Updater - ERROR - Error while getting Updates: Conflict: terminated by other getUpdates request; make sure that only one bot instance is running
telegram.ext.Application - ERROR - An error was raised and an uncaught error was raised while handling the error with an error_handler.
Traceback (most recent call last):
  File "E:\Aviraj_python\theclassmatebot\.venv\Lib\site-packages\telegram\ext\_application.py", line 1740, in process_error
    await callback(update, context)
  File "e:\Aviraj_python\theclassmatebot\src\main.py", line 219, in error
    f"Update {update} caused the following error {context.error}-{ str(datetime.now())}"
TypeError: error() missing 1 required positional argument: 'context'
telegram.ext.Updater - ERROR - Error while getting Updates: Conflict: terminated by other getUpdates request; make sure that only one bot instance is running
telegram.ext.Application - ERROR - An error was raised and an uncaught error was raised while handling the error with an error_handler.
Traceback (most recent call last):
  File "e:\Aviraj_python\theclassmatebot\.venv\Lib\site-packages\telegram\ext\_application.py", line 1740, in process_error
    await callback(update, context)
  File "e:\Aviraj_python\theclassmatebot\src\main.py", line 218, in error
    error(
TypeError: error() missing 1 required positional argument: 'context'
telegram.ext.Updater - ERROR - Error while getting Updates: Conflict: terminated by other getUpdates request; make sure that only one bot instance is running
telegram.ext.Application - ERROR - An error was raised and an uncaught error was raised while handling the error with an error_handler.
Traceback (most recent call last):
  File "E:\Aviraj_python\theclassmatebot\.venv\Lib\site-packages\telegram\ext\_application.py", line 1740, in process_error
    await callback(update, context)
  File "e:\Aviraj_python\theclassmatebot\src\main.py", line 219, in error
    f"Update {update} caused the following error {context.error}-{ str(datetime.now())}"
TypeError: error() missing 1 required positional argument: 'context'
telegram.ext.Updater - ERROR - Error while getting Updates: Conflict: terminated by other getUpdates request; make sure that only one bot instance is running
telegram.ext.Application - ERROR - An error was raised and an uncaught error was raised while handling the error with an error_handler.
Traceback (most recent call last):
  File "e:\Aviraj_python\theclassmatebot\.venv\Lib\site-packages\telegram\ext\_application.py", line 1740, in process_error
    await callback(update, context)
  File "e:\Aviraj_python\theclassmatebot\src\main.py", line 218, in error
    error(
TypeError: error() missing 1 required positional argument: 'context'
telegram.ext.Updater - ERROR - Error while getting Updates: Conflict: terminated by other getUpdates request; make sure that only one bot instance is running
telegram.ext.Application - ERROR - An error was raised and an uncaught error was raised while handling the error with an error_handler.
Traceback (most recent call last):
  File "E:\Aviraj_python\theclassmatebot\.venv\Lib\site-packages\telegram\ext\_application.py", line 1740, in process_error
    await callback(update, context)
  File "e:\Aviraj_python\theclassmatebot\src\main.py", line 219, in error
    f"Update {update} caused the following error {context.error}-{ str(datetime.now())}"
TypeError: error() missing 1 required positional argument: 'context'
telegram.ext.Updater - ERROR - Error while getting Updates: Conflict: terminated by other getUpdates request; make sure that only one bot instance is running
telegram.ext.Application - ERROR - An error was raised and an uncaught error was raised while handling the error with an error_handler.
Traceback (most recent call last):
  File "e:\Aviraj_python\theclassmatebot\.venv\Lib\site-packages\telegram\ext\_application.py", line 1740, in process_error
    await callback(update, context)
  File "e:\Aviraj_python\theclassmatebot\src\main.py", line 218, in error
    error(
TypeError: error() missing 1 required positional argument: 'context'
telegram.ext.Updater - ERROR - Error while getting Updates: Conflict: terminated by other getUpdates request; make sure that only one bot instance is running
telegram.ext.Application - ERROR - An error was raised and an uncaught error was raised while handling the error with an error_handler.
Traceback (most recent call last):
  File "E:\Aviraj_python\theclassmatebot\.venv\Lib\site-packages\telegram\ext\_application.py", line 1740, in process_error
    await callback(update, context)
  File "e:\Aviraj_python\theclassmatebot\src\main.py", line 219, in error
    f"Update {update} caused the following error {context.error}-{ str(datetime.now())}"
TypeError: error() missing 1 required positional argument: 'context'
telegram.ext.Updater - ERROR - Error while getting Updates: Conflict: terminated by other getUpdates request; make sure that only one bot instance is running
telegram.ext.Application - ERROR - An error was raised and an uncaught error was raised while handling the error with an error_handler.
Traceback (most recent call last):
  File "e:\Aviraj_python\theclassmatebot\.venv\Lib\site-packages\telegram\ext\_application.py", line 1740, in process_error
    await callback(update, context)
  File "e:\Aviraj_python\theclassmatebot\src\main.py", line 218, in error
    error(
TypeError: error() missing 1 required positional argument: 'context'
telegram.ext.Updater - ERROR - Error while getting Updates: Conflict: terminated by other getUpdates request; make sure that only one bot instance is running
telegram.ext.Application - ERROR - An error was raised and an uncaught error was raised while handling the error with an error_handler.
Traceback (most recent call last):
  File "E:\Aviraj_python\theclassmatebot\.venv\Lib\site-packages\telegram\ext\_application.py", line 1740, in process_error
    await callback(update, context)
  File "e:\Aviraj_python\theclassmatebot\src\main.py", line 219, in error
    f"Update {update} caused the following error {context.error}-{ str(datetime.now())}"
TypeError: error() missing 1 required positional argument: 'context'
telegram.ext.Updater - ERROR - Error while getting Updates: Conflict: terminated by other getUpdates request; make sure that only one bot instance is running
telegram.ext.Application - ERROR - An error was raised and an uncaught error was raised while handling the error with an error_handler.
Traceback (most recent call last):
  File "e:\Aviraj_python\theclassmatebot\.venv\Lib\site-packages\telegram\ext\_application.py", line 1740, in process_error
    await callback(update, context)
  File "e:\Aviraj_python\theclassmatebot\src\main.py", line 218, in error
    error(
TypeError: error() missing 1 required positional argument: 'context'
telegram.ext.Updater - ERROR - Error while getting Updates: Conflict: terminated by other getUpdates request; make sure that only one bot instance is running
telegram.ext.Application - ERROR - An error was raised and an uncaught error was raised while handling the error with an error_handler.
Traceback (most recent call last):
  File "E:\Aviraj_python\theclassmatebot\.venv\Lib\site-packages\telegram\ext\_application.py", line 1740, in process_error
    await callback(update, context)
  File "e:\Aviraj_python\theclassmatebot\src\main.py", line 219, in error
    f"Update {update} caused the following error {context.error}-{ str(datetime.now())}"
TypeError: error() missing 1 required positional argument: 'context'
telegram.ext.Updater - ERROR - Error while getting Updates: Conflict: terminated by other getUpdates request; make sure that only one bot instance is running
telegram.ext.Application - ERROR - An error was raised and an uncaught error was raised while handling the error with an error_handler.
Traceback (most recent call last):
  File "e:\Aviraj_python\theclassmatebot\.venv\Lib\site-packages\telegram\ext\_application.py", line 1740, in process_error
    await callback(update, context)
  File "e:\Aviraj_python\theclassmatebot\src\main.py", line 218, in error
    error(
TypeError: error() missing 1 required positional argument: 'context'
telegram.ext.Updater - ERROR - Error while getting Updates: Conflict: terminated by other getUpdates request; make sure that only one bot instance is running
telegram.ext.Application - ERROR - An error was raised and an uncaught error was raised while handling the error with an error_handler.
Traceback (most recent call last):
  File "E:\Aviraj_python\theclassmatebot\.venv\Lib\site-packages\telegram\ext\_application.py", line 1740, in process_error
    await callback(update, context)
  File "e:\Aviraj_python\theclassmatebot\src\main.py", line 219, in error
    f"Update {update} caused the following error {context.error}-{ str(datetime.now())}"
TypeError: error() missing 1 required positional argument: 'context'
telegram.ext.Updater - ERROR - Error while getting Updates: Conflict: terminated by other getUpdates request; make sure that only one bot instance is running
telegram.ext.Application - ERROR - An error was raised and an uncaught error was raised while handling the error with an error_handler.
Traceback (most recent call last):
  File "E:\Aviraj_python\theclassmatebot\.venv\Lib\site-packages\telegram\ext\_application.py", line 1740, in process_error
    await callback(update, context)
  File "e:\Aviraj_python\theclassmatebot\src\main.py", line 219, in error
    f"Update {update} caused the following error {context.error}-{ str(datetime.now())}"
TypeError: error() missing 1 required positional argument: 'context'
telegram.ext.Updater - ERROR - Error while getting Updates: Conflict: terminated by other getUpdates request; make sure that only one bot instance is running
telegram.ext.Application - ERROR - An error was raised and an uncaught error was raised while handling the error with an error_handler.
Traceback (most recent call last):
  File "e:\Aviraj_python\theclassmatebot\.venv\Lib\site-packages\telegram\ext\_application.py", line 1740, in process_error
    await callback(update, context)
  File "e:\Aviraj_python\theclassmatebot\src\main.py", line 218, in error
    error(
TypeError: error() missing 1 required positional argument: 'context'
telegram.ext.Updater - ERROR - Error while getting Updates: Conflict: terminated by other getUpdates request; make sure that only one bot instance is running
telegram.ext.Application - ERROR - An error was raised and an uncaught error was raised while handling the error with an error_handler.
Traceback (most recent call last):
  File "E:\Aviraj_python\theclassmatebot\.venv\Lib\site-packages\telegram\ext\_application.py", line 1740, in process_error
    await callback(update, context)
  File "e:\Aviraj_python\theclassmatebot\src\main.py", line 219, in error
    f"Update {update} caused the following error {context.error}-{ str(datetime.now())}"
TypeError: error() missing 1 required positional argument: 'context'
telegram.ext.Updater - ERROR - Error while getting Updates: Conflict: terminated by other getUpdates request; make sure that only one bot instance is running
telegram.ext.Application - ERROR - An error was raised and an uncaught error was raised while handling the error with an error_handler.
Traceback (most recent call last):
  File "E:\Aviraj_python\theclassmatebot\.venv\Lib\site-packages\telegram\ext\_application.py", line 1740, in process_error
    await callback(update, context)
  File "e:\Aviraj_python\theclassmatebot\src\main.py", line 219, in error
    f"Update {update} caused the following error {context.error}-{ str(datetime.now())}"
TypeError: error() missing 1 required positional argument: 'context'
root - WARNING - Bot is currently online-2023-10-19 20:47:37.685248
root - WARNING - Bot is currently polling-2023-10-19 20:47:37.716498
asyncio - ERROR - Task was destroyed but it is pending!
task: <Task pending name='Application:6544496390:update_fetcher' coro=<Application._update_fetcher() running at E:\Aviraj_python\theclassmatebot\.venv\Lib\site-packages\telegram\ext\_application.py:1101> wait_for=<Future pending cb=[Task.task_wakeup()]>>
root - WARNING - Bot is currently online-2023-10-19 21:06:29.378115
root - WARNING - Bot is currently polling-2023-10-19 21:06:29.400262
telegram.ext.Application - ERROR - An error was raised and an uncaught error was raised while handling the error with an error_handler.
Traceback (most recent call last):
  File "e:\Aviraj_python\theclassmatebot\.venv\Lib\site-packages\telegram\ext\_application.py", line 1184, in process_update
    await coroutine
  File "e:\Aviraj_python\theclassmatebot\.venv\Lib\site-packages\telegram\ext\_basehandler.py", line 141, in handle_update
    return await self.callback(update, context)
           ^^^^^^^^^^^^^^^^^^^^^^^^^^^^^^^^^^^^
  File "e:\Aviraj_python\theclassmatebot\src\commands.py", line 248, in cancel_command
    if any((user_message_mode,)):
            ^^^^^^^^^^^^^^^^^
NameError: name 'user_message_mode' is not defined

During handling of the above exception, another exception occurred:

Traceback (most recent call last):
  File "e:\Aviraj_python\theclassmatebot\.venv\Lib\site-packages\telegram\ext\_application.py", line 1740, in process_error
    await callback(update, context)
  File "e:\Aviraj_python\theclassmatebot\src\main.py", line 213, in error
    error(
TypeError: error() missing 1 required positional argument: 'context'
telegram.ext.Application - ERROR - An error was raised and an uncaught error was raised while handling the error with an error_handler.
Traceback (most recent call last):
  File "e:\Aviraj_python\theclassmatebot\.venv\Lib\site-packages\telegram\ext\_application.py", line 1184, in process_update
    await coroutine
  File "e:\Aviraj_python\theclassmatebot\.venv\Lib\site-packages\telegram\ext\_basehandler.py", line 141, in handle_update
    return await self.callback(update, context)
           ^^^^^^^^^^^^^^^^^^^^^^^^^^^^^^^^^^^^
  File "e:\Aviraj_python\theclassmatebot\src\commands.py", line 248, in cancel_command
    if any((user_message_mode,)):
            ^^^^^^^^^^^^^^^^^
NameError: name 'user_message_mode' is not defined

During handling of the above exception, another exception occurred:

Traceback (most recent call last):
  File "e:\Aviraj_python\theclassmatebot\.venv\Lib\site-packages\telegram\ext\_application.py", line 1740, in process_error
    await callback(update, context)
  File "e:\Aviraj_python\theclassmatebot\src\main.py", line 213, in error
    error(
TypeError: error() missing 1 required positional argument: 'context'
root - WARNING - User:6310472157 :Hi-2023-10-19 21:07:18.553281
root - WARNING - User:6310472157 :Hi-2023-10-19 21:07:41.383310
root - WARNING - User:6310472157 :Test-2023-10-19 21:08:18.342483
root - WARNING - Bot is currently online-2023-10-19 21:18:46.177906
root - WARNING - Bot is currently polling-2023-10-19 21:18:46.193977
root - WARNING - Bot is currently online-2023-10-19 21:23:39.447150
root - WARNING - Bot is currently polling-2023-10-19 21:23:39.471152
telegram.ext.Application - ERROR - An error was raised and an uncaught error was raised while handling the error with an error_handler.
Traceback (most recent call last):
  File "e:\Aviraj_python\theclassmatebot\.venv\Lib\site-packages\telegram\ext\_application.py", line 1184, in process_update
    await coroutine
  File "e:\Aviraj_python\theclassmatebot\.venv\Lib\site-packages\telegram\ext\_basehandler.py", line 141, in handle_update
    return await self.callback(update, context)
           ^^^^^^^^^^^^^^^^^^^^^^^^^^^^^^^^^^^^
  File "e:\Aviraj_python\theclassmatebot\src\commands.py", line 254, in cancel_command
    if any((user_message_mode,)):
            ^^^^^^^^^^^^^^^^^
UnboundLocalError: cannot access local variable 'user_message_mode' where it is not associated with a value

During handling of the above exception, another exception occurred:

Traceback (most recent call last):
  File "e:\Aviraj_python\theclassmatebot\.venv\Lib\site-packages\telegram\ext\_application.py", line 1740, in process_error
    await callback(update, context)
  File "e:\Aviraj_python\theclassmatebot\src\main.py", line 225, in error
    error(
TypeError: error() missing 1 required positional argument: 'context'
telegram.ext.Application - ERROR - An error was raised and an uncaught error was raised while handling the error with an error_handler.
Traceback (most recent call last):
  File "e:\Aviraj_python\theclassmatebot\.venv\Lib\site-packages\telegram\ext\_application.py", line 1184, in process_update
    await coroutine
  File "e:\Aviraj_python\theclassmatebot\.venv\Lib\site-packages\telegram\ext\_basehandler.py", line 141, in handle_update
    return await self.callback(update, context)
           ^^^^^^^^^^^^^^^^^^^^^^^^^^^^^^^^^^^^
  File "e:\Aviraj_python\theclassmatebot\src\commands.py", line 254, in cancel_command
    if any((user_message_mode,)):
            ^^^^^^^^^^^^^^^^^
UnboundLocalError: cannot access local variable 'user_message_mode' where it is not associated with a value

During handling of the above exception, another exception occurred:

Traceback (most recent call last):
  File "e:\Aviraj_python\theclassmatebot\.venv\Lib\site-packages\telegram\ext\_application.py", line 1740, in process_error
    await callback(update, context)
  File "e:\Aviraj_python\theclassmatebot\src\main.py", line 225, in error
    error(
TypeError: error() missing 1 required positional argument: 'context'
telegram.ext.Application - ERROR - An error was raised and an uncaught error was raised while handling the error with an error_handler.
Traceback (most recent call last):
  File "e:\Aviraj_python\theclassmatebot\.venv\Lib\site-packages\telegram\ext\_application.py", line 1184, in process_update
    await coroutine
  File "e:\Aviraj_python\theclassmatebot\.venv\Lib\site-packages\telegram\ext\_basehandler.py", line 141, in handle_update
    return await self.callback(update, context)
           ^^^^^^^^^^^^^^^^^^^^^^^^^^^^^^^^^^^^
  File "e:\Aviraj_python\theclassmatebot\src\commands.py", line 254, in cancel_command
    if any((user_message_mode,)):
            ^^^^^^^^^^^^^^^^^
UnboundLocalError: cannot access local variable 'user_message_mode' where it is not associated with a value

During handling of the above exception, another exception occurred:

Traceback (most recent call last):
  File "e:\Aviraj_python\theclassmatebot\.venv\Lib\site-packages\telegram\ext\_application.py", line 1740, in process_error
    await callback(update, context)
  File "e:\Aviraj_python\theclassmatebot\src\main.py", line 225, in error
    error(
TypeError: error() missing 1 required positional argument: 'context'
root - WARNING - Bot is currently online-2023-10-19 21:26:45.672542
root - WARNING - Bot is currently polling-2023-10-19 21:26:45.696539
telegram.ext.Application - ERROR - An error was raised and an uncaught error was raised while handling the error with an error_handler.
Traceback (most recent call last):
  File "e:\Aviraj_python\theclassmatebot\.venv\Lib\site-packages\telegram\ext\_application.py", line 1184, in process_update
    await coroutine
  File "e:\Aviraj_python\theclassmatebot\.venv\Lib\site-packages\telegram\ext\_basehandler.py", line 141, in handle_update
    return await self.callback(update, context)
                 ^^^^^^^^^^^^^^^^^^^^^^^^^^^^^^
TypeError: cancel_command() missing 1 required positional argument: 'current_mode'

During handling of the above exception, another exception occurred:

Traceback (most recent call last):
  File "e:\Aviraj_python\theclassmatebot\.venv\Lib\site-packages\telegram\ext\_application.py", line 1740, in process_error
    await callback(update, context)
  File "e:\Aviraj_python\theclassmatebot\src\main.py", line 225, in error
    error(
TypeError: error() missing 1 required positional argument: 'context'
root - WARNING - Bot is currently online-2023-10-19 21:27:57.920171
root - WARNING - Bot is currently polling-2023-10-19 21:27:57.945168
root - WARNING - Bot is currently online-2023-10-19 21:39:38.342647
root - WARNING - Bot is currently polling-2023-10-19 21:39:38.366647
root - WARNING - Bot is currently online-2023-10-19 21:41:33.806976
root - WARNING - Bot is currently polling-2023-10-19 21:41:33.831116
asyncio - ERROR - Task was destroyed but it is pending!
task: <Task pending name='Application:6544496390:update_fetcher' coro=<Application._update_fetcher() running at E:\Aviraj_python\theclassmatebot\.venv\Lib\site-packages\telegram\ext\_application.py:1101> wait_for=<Future pending cb=[Task.task_wakeup()]>>
root - WARNING - Bot is currently online-2023-10-19 21:42:16.073559
root - WARNING - Bot is currently polling-2023-10-19 21:42:16.104812
root - WARNING - User:6310472157 :Hi-2023-10-19 21:43:19.895135
root - WARNING - Bot is currently online-2023-10-19 21:47:52.074865
root - WARNING - Bot is currently polling-2023-10-19 21:47:52.106120
root - WARNING - User:6310472157 :Hi-2023-10-19 21:48:02.537297
root - WARNING - User:6310472157 :Hi-2023-10-19 21:48:10.725803
root - WARNING - User:6310472157 :Hi-2023-10-19 21:48:16.621592
root - WARNING - User:6310472157 :Hi-2023-10-19 21:49:20.508784
root - WARNING - User:6310472157 :Feedback-2023-10-19 21:49:29.082729
root - WARNING - User:6310472157 :Hi-2023-10-19 21:50:26.114690
root - WARNING - Bot is currently online-2023-10-19 21:58:25.975614
root - WARNING - Bot is currently polling-2023-10-19 21:58:26.005784
root - WARNING - Bot is currently online-2023-10-19 22:05:08.058058
root - WARNING - Bot is currently polling-2023-10-19 22:05:08.073696
telegram.ext.Application - ERROR - An error was raised and an uncaught error was raised while handling the error with an error_handler.
Traceback (most recent call last):
  File "e:\Aviraj_python\theclassmatebot\.venv\Lib\site-packages\telegram\ext\_application.py", line 1184, in process_update
    await coroutine
  File "e:\Aviraj_python\theclassmatebot\.venv\Lib\site-packages\telegram\ext\_basehandler.py", line 141, in handle_update
    return await self.callback(update, context)
           ^^^^^^^^^^^^^^^^^^^^^^^^^^^^^^^^^^^^
  File "e:\Aviraj_python\theclassmatebot\src\main.py", line 168, in handle_message
    await feedback_receive(update, context, set_message_mode_callback)
  File "e:\Aviraj_python\theclassmatebot\src\modes.py", line 36, in feedback_receive
    feedback_file.write(f"\n{str(datetime.now())}: " + user_message)
                                 ^^^^^^^^^^^^
AttributeError: module 'datetime' has no attribute 'now'

During handling of the above exception, another exception occurred:

Traceback (most recent call last):
  File "e:\Aviraj_python\theclassmatebot\.venv\Lib\site-packages\telegram\ext\_application.py", line 1740, in process_error
    await callback(update, context)
  File "e:\Aviraj_python\theclassmatebot\src\main.py", line 186, in error
    error(
TypeError: error() missing 1 required positional argument: 'context'
root - WARNING - Bot is currently online-2023-10-19 22:09:26.598408
root - WARNING - Bot is currently polling-2023-10-19 22:09:26.638187
telegram.ext.Application - ERROR - An error was raised and an uncaught error was raised while handling the error with an error_handler.
Traceback (most recent call last):
  File "e:\Aviraj_python\theclassmatebot\.venv\Lib\site-packages\telegram\ext\_application.py", line 1184, in process_update
    await coroutine
  File "e:\Aviraj_python\theclassmatebot\.venv\Lib\site-packages\telegram\ext\_basehandler.py", line 141, in handle_update
    return await self.callback(update, context)
           ^^^^^^^^^^^^^^^^^^^^^^^^^^^^^^^^^^^^
  File "e:\Aviraj_python\theclassmatebot\src\main.py", line 171, in handle_message
    await enquiry_receive(update, context, set_message_mode_callback, text)
  File "e:\Aviraj_python\theclassmatebot\src\modes.py", line 61, in enquiry_receive
    f"\n{str(datetime.now())}: {update.message.chat.username}: "
             ^^^^^^^^^^^^
AttributeError: module 'datetime' has no attribute 'now'

During handling of the above exception, another exception occurred:

Traceback (most recent call last):
  File "e:\Aviraj_python\theclassmatebot\.venv\Lib\site-packages\telegram\ext\_application.py", line 1740, in process_error
    await callback(update, context)
  File "e:\Aviraj_python\theclassmatebot\src\main.py", line 186, in error
    error(
TypeError: error() missing 1 required positional argument: 'context'
telegram.ext.Application - ERROR - An error was raised and an uncaught error was raised while handling the error with an error_handler.
Traceback (most recent call last):
  File "e:\Aviraj_python\theclassmatebot\.venv\Lib\site-packages\telegram\ext\_application.py", line 1184, in process_update
    await coroutine
  File "e:\Aviraj_python\theclassmatebot\.venv\Lib\site-packages\telegram\ext\_basehandler.py", line 141, in handle_update
    return await self.callback(update, context)
           ^^^^^^^^^^^^^^^^^^^^^^^^^^^^^^^^^^^^
  File "e:\Aviraj_python\theclassmatebot\src\main.py", line 168, in handle_message
    await feedback_receive(update, context, set_message_mode_callback, text)
  File "e:\Aviraj_python\theclassmatebot\src\modes.py", line 36, in feedback_receive
    feedback_file.write(f"\n{str(datetime.now())}: " + user_message)
                                 ^^^^^^^^^^^^
AttributeError: module 'datetime' has no attribute 'now'

During handling of the above exception, another exception occurred:

Traceback (most recent call last):
  File "e:\Aviraj_python\theclassmatebot\.venv\Lib\site-packages\telegram\ext\_application.py", line 1740, in process_error
    await callback(update, context)
  File "e:\Aviraj_python\theclassmatebot\src\main.py", line 186, in error
    error(
TypeError: error() missing 1 required positional argument: 'context'
root - WARNING - Bot is currently online-2023-10-19 22:13:19.034905
root - WARNING - Bot is currently polling-2023-10-19 22:13:19.068673
telegram.ext.Application - ERROR - An error was raised and an uncaught error was raised while handling the error with an error_handler.
Traceback (most recent call last):
  File "e:\Aviraj_python\theclassmatebot\.venv\Lib\site-packages\telegram\ext\_application.py", line 1184, in process_update
    await coroutine
  File "e:\Aviraj_python\theclassmatebot\.venv\Lib\site-packages\telegram\ext\_basehandler.py", line 141, in handle_update
    return await self.callback(update, context)
           ^^^^^^^^^^^^^^^^^^^^^^^^^^^^^^^^^^^^
  File "e:\Aviraj_python\theclassmatebot\src\main.py", line 168, in handle_message
    await feedback_receive(update, context, set_message_mode_callback, text)
  File "e:\Aviraj_python\theclassmatebot\src\modes.py", line 36, in feedback_receive
    feedback_file.write(f"\n{str(datetime.now())}: " + user_message)
                                 ^^^^^^^^^^^^
AttributeError: module 'datetime' has no attribute 'now'

During handling of the above exception, another exception occurred:

Traceback (most recent call last):
  File "e:\Aviraj_python\theclassmatebot\.venv\Lib\site-packages\telegram\ext\_application.py", line 1740, in process_error
    await callback(update, context)
  File "e:\Aviraj_python\theclassmatebot\src\main.py", line 186, in error
    error(
TypeError: error() missing 1 required positional argument: 'context'
root - WARNING - User:6310472157 :Feedback-2023-10-19 22:13:59.697101
asyncio - ERROR - Task was destroyed but it is pending!
task: <Task pending name='Application:6544496390:update_fetcher' coro=<Application._update_fetcher() running at e:\Aviraj_python\theclassmatebot\.venv\Lib\site-packages\telegram\ext\_application.py:1101> wait_for=<Future pending cb=[Task.task_wakeup()]>>
root - WARNING - Bot is currently online-2023-10-19 22:17:10.623600
root - WARNING - Bot is currently polling-2023-10-19 22:17:10.654862
telegram.ext.Application - ERROR - An error was raised and an uncaught error was raised while handling the error with an error_handler.
Traceback (most recent call last):
  File "e:\Aviraj_python\theclassmatebot\.venv\Lib\site-packages\telegram\ext\_application.py", line 1184, in process_update
    await coroutine
  File "e:\Aviraj_python\theclassmatebot\.venv\Lib\site-packages\telegram\ext\_basehandler.py", line 141, in handle_update
    return await self.callback(update, context)
           ^^^^^^^^^^^^^^^^^^^^^^^^^^^^^^^^^^^^
  File "e:\Aviraj_python\theclassmatebot\src\main.py", line 168, in handle_message
    await feedback_receive(update, context, set_message_mode_callback, text)
  File "e:\Aviraj_python\theclassmatebot\src\modes.py", line 36, in feedback_receive
    feedback_file.write(f"\n{str(datetime.now())}: " + user_message)
                                 ^^^^^^^^^^^^
AttributeError: module 'datetime' has no attribute 'now'

During handling of the above exception, another exception occurred:

Traceback (most recent call last):
  File "e:\Aviraj_python\theclassmatebot\.venv\Lib\site-packages\telegram\ext\_application.py", line 1740, in process_error
    await callback(update, context)
  File "e:\Aviraj_python\theclassmatebot\src\main.py", line 186, in error
    error(
TypeError: error() missing 1 required positional argument: 'context'
root - WARNING - Bot is currently online-2023-10-20 12:40:07.448783
root - WARNING - Bot is currently polling-2023-10-20 12:40:07.577291
telegram.ext.Application - ERROR - An error was raised and an uncaught error was raised while handling the error with an error_handler.
Traceback (most recent call last):
  File "E:\Aviraj_python\theclassmatebot\.venv\Lib\site-packages\telegram\ext\_application.py", line 1184, in process_update
    await coroutine
  File "E:\Aviraj_python\theclassmatebot\.venv\Lib\site-packages\telegram\ext\_basehandler.py", line 141, in handle_update
    return await self.callback(update, context)
           ^^^^^^^^^^^^^^^^^^^^^^^^^^^^^^^^^^^^
  File "e:\Aviraj_python\theclassmatebot\src\main.py", line 168, in handle_message
    await feedback_receive(update, context, set_message_mode_callback, text)
  File "e:\Aviraj_python\theclassmatebot\src\modes.py", line 36, in feedback_receive
    feedback_file.write(f"\n{str(datetime.now())}: " + user_message)
                                 ^^^^^^^^^^^^
AttributeError: module 'datetime' has no attribute 'now'

During handling of the above exception, another exception occurred:

Traceback (most recent call last):
  File "E:\Aviraj_python\theclassmatebot\.venv\Lib\site-packages\telegram\ext\_application.py", line 1740, in process_error
    await callback(update, context)
  File "e:\Aviraj_python\theclassmatebot\src\main.py", line 186, in error
    error(
TypeError: error() missing 1 required positional argument: 'context'
telegram.ext.Application - ERROR - An error was raised and an uncaught error was raised while handling the error with an error_handler.
Traceback (most recent call last):
  File "E:\Aviraj_python\theclassmatebot\.venv\Lib\site-packages\telegram\ext\_application.py", line 1184, in process_update
    await coroutine
  File "E:\Aviraj_python\theclassmatebot\.venv\Lib\site-packages\telegram\ext\_basehandler.py", line 141, in handle_update
    return await self.callback(update, context)
           ^^^^^^^^^^^^^^^^^^^^^^^^^^^^^^^^^^^^
  File "e:\Aviraj_python\theclassmatebot\src\main.py", line 168, in handle_message
    await feedback_receive(update, context, set_message_mode_callback, text)
  File "e:\Aviraj_python\theclassmatebot\src\modes.py", line 36, in feedback_receive
    feedback_file.write(f"\n{str(datetime.now())}: " + user_message)
                                 ^^^^^^^^^^^^
AttributeError: module 'datetime' has no attribute 'now'

During handling of the above exception, another exception occurred:

Traceback (most recent call last):
  File "E:\Aviraj_python\theclassmatebot\.venv\Lib\site-packages\telegram\ext\_application.py", line 1740, in process_error
    await callback(update, context)
  File "e:\Aviraj_python\theclassmatebot\src\main.py", line 186, in error
    error(
TypeError: error() missing 1 required positional argument: 'context'
root - WARNING - Bot is currently online-2023-10-20 12:43:03.096584
root - WARNING - Bot is currently polling-2023-10-20 12:43:03.127834
root - WARNING - User:6310472157 :Hi-2023-10-20 12:43:19.154561
root - WARNING - Bot is currently online-2023-10-20 13:07:00.857493
root - WARNING - Bot is currently polling-2023-10-20 13:07:00.898890
root - WARNING - User:6310472157 :Hi-2023-10-20 13:07:24.807810
root - WARNING - Bot is currently online-2023-11-14 18:38:54.511348
root - WARNING - Bot is currently polling-2023-11-14 18:38:54.641481
telegram.ext.Application - ERROR - An error was raised and an uncaught error was raised while handling the error with an error_handler.
Traceback (most recent call last):
  File "e:\Aviraj_python\theclassmatebot\.venv\Lib\site-packages\telegram\ext\_application.py", line 1184, in process_update
    await coroutine
  File "e:\Aviraj_python\theclassmatebot\.venv\Lib\site-packages\telegram\ext\_basehandler.py", line 141, in handle_update
    return await self.callback(update, context)
                 ^^^^^^^^^^^^^^^^^^^^^^^^^^^^^^
TypeError: activate_command() missing 1 required positional argument: 'context'

During handling of the above exception, another exception occurred:

Traceback (most recent call last):
  File "e:\Aviraj_python\theclassmatebot\.venv\Lib\site-packages\telegram\ext\_application.py", line 1740, in process_error
    await callback(update, context)
  File "e:\Aviraj_python\theclassmatebot\src\main.py", line 188, in error
    error(
TypeError: error() missing 1 required positional argument: 'context'
root - WARNING - User:6310472157 :Hi-2023-11-14 18:39:11.182015
root - WARNING - Bot is currently online-2023-11-14 18:41:17.399459
root - WARNING - Bot is currently polling-2023-11-14 18:41:17.425462
telegram.ext.Application - ERROR - An error was raised and an uncaught error was raised while handling the error with an error_handler.
Traceback (most recent call last):
  File "e:\Aviraj_python\theclassmatebot\.venv\Lib\site-packages\telegram\ext\_application.py", line 1184, in process_update
    await coroutine
  File "e:\Aviraj_python\theclassmatebot\.venv\Lib\site-packages\telegram\ext\_basehandler.py", line 141, in handle_update
    return await self.callback(update, context)
                 ^^^^^^^^^^^^^^^^^^^^^^^^^^^^^^
TypeError: activate_command() got multiple values for argument 'callback_function'

During handling of the above exception, another exception occurred:

Traceback (most recent call last):
  File "e:\Aviraj_python\theclassmatebot\.venv\Lib\site-packages\telegram\ext\_application.py", line 1740, in process_error
    await callback(update, context)
  File "e:\Aviraj_python\theclassmatebot\src\main.py", line 188, in error
    error(
TypeError: error() missing 1 required positional argument: 'context'
telegram.ext.Application - ERROR - An error was raised and an uncaught error was raised while handling the error with an error_handler.
Traceback (most recent call last):
  File "e:\Aviraj_python\theclassmatebot\.venv\Lib\site-packages\telegram\ext\_application.py", line 1184, in process_update
    await coroutine
  File "e:\Aviraj_python\theclassmatebot\.venv\Lib\site-packages\telegram\ext\_basehandler.py", line 141, in handle_update
    return await self.callback(update, context)
                 ^^^^^^^^^^^^^^^^^^^^^^^^^^^^^^
TypeError: activate_command() got multiple values for argument 'callback_function'

During handling of the above exception, another exception occurred:

Traceback (most recent call last):
  File "e:\Aviraj_python\theclassmatebot\.venv\Lib\site-packages\telegram\ext\_application.py", line 1740, in process_error
    await callback(update, context)
  File "e:\Aviraj_python\theclassmatebot\src\main.py", line 188, in error
    error(
TypeError: error() missing 1 required positional argument: 'context'
root - WARNING - Bot is currently online-2023-11-14 18:44:51.683046
root - WARNING - Bot is currently polling-2023-11-14 18:44:51.714299
root - WARNING - User:6310472157 :/profile-2023-11-14 18:45:50.483038
root - WARNING - Bot is currently online-2023-11-15 10:54:57.065434
root - WARNING - Bot is currently polling-2023-11-15 10:54:57.112315
root - WARNING - User:6310472157 :Hu-2023-11-15 10:55:25.725766
root - WARNING - Bot is currently online-2023-11-15 10:56:36.292557
root - WARNING - Bot is currently polling-2023-11-15 10:56:36.330335
root - WARNING - Bot is currently online-2023-11-15 11:00:49.036081
root - WARNING - Bot is currently polling-2023-11-15 11:00:49.067301
root - WARNING - Bot is currently online-2023-11-15 11:03:39.012710
root - WARNING - Bot is currently polling-2023-11-15 11:03:39.043965
root - WARNING - User:6310472157 :/myprofile-2023-11-15 11:03:55.363343
root - WARNING - Bot is currently online-2023-11-15 11:05:10.997405
root - WARNING - Bot is currently polling-2023-11-15 11:05:11.035193
root - WARNING - Bot is currently online-2023-11-15 11:06:02.176087
root - WARNING - Bot is currently polling-2023-11-15 11:06:02.221342
root - WARNING - Bot is currently online-2023-11-15 11:06:33.113849
root - WARNING - Bot is currently polling-2023-11-15 11:06:33.145114
root - WARNING - Bot is currently online-2023-11-15 11:07:53.728211
root - WARNING - Bot is currently polling-2023-11-15 11:07:53.781631
root - WARNING - Bot is currently online-2023-11-15 11:10:45.260830
root - WARNING - Bot is currently polling-2023-11-15 11:10:45.292083
root - WARNING - Bot is currently online-2023-11-16 17:46:31.229957
root - WARNING - Bot is currently polling-2023-11-16 17:46:31.448700
root - WARNING - Bot is currently online-2023-11-16 17:52:41.629795
root - WARNING - Bot is currently polling-2023-11-16 17:52:41.661053
root - WARNING - Bot is currently online-2023-11-16 17:57:18.593765
root - WARNING - Bot is currently polling-2023-11-16 17:57:18.625013
